Workbook

Sheet Email
A1: Hey, The board is asking to see how volume looked in Q2. I got some data (attached), but didn’t have a chance to pull anything together and was hoping you could take a stab at it. I think they just want to see Q2 2021 volume by region and wanted to know if everything was looking good. I think this file has what you need. I don’t remember all the region codes – I know NAM ends in 1, EMEA ends in 3 and APAC and LATAM are 2 and 4, but I don’t remember which is which. I do know LATAM has the lowest volume so just go ahead and assign that to which ever comes out lowest. I appreciate your help!

Sheet Pivot
A3: Sum of Vol | B3: Column Labels
A4: Row Labels | B4: NAM | C4: EMEA | D4: APAC | E4: LATAM
A5: 2020
A6: Qtr1 | B6: 509419 | C6: 147852 | D6: 95736 | E6: 69053
A7: Qtr2 | B7: 576618 | C7: 173566 | D7: 107338 | E7: 82618
A8: Qtr3 | B8: 363694 | C8: 103536 | D8: 69198 | E8: 50574
A9: Qtr4 | B9: 432034 | C9: 129264 | D9: 80144 | E9: 65121
A10: 2021
A11: Qtr1 | B11: 530019 | C11: 150204 | D11: 99778 | E11: 75265
A12: Qtr2 | B12: 596502 | C12: 176338 | D12: 109811 | E12: 82631
A13: Grand Total | B13: 3008286 | C13: 880760 | D13: 562005 | E13: 425262
A38: Sum of Vol | B38: Column Labels
B39: 2020 | F39: 2021
B40: Qtr1 | C40: Qtr2 | D40: Qtr3 | E40: Qtr4 | F40: Qtr1 | G40: Qtr2 | J40: Q1 YoY | M40: Q2 YoY
A41: Row Labels | J41: # | K41: % | M41: # | N41: % | P41: Q2 Fcst
A42: NAM | B42: 509419 | C42: 576618 | D42: 363694 | E42: 432034 | F42: 530019 | G42: 596502 | I42: NAM | J42: =F42-B42 -> 20600 | K42: =F42/B42-1 -> 0.040438225 | M42: =G42-C42 -> 19884 | N42: =G42/C42-1 -> 0.034483835 | P42: =C42/(1-K42) -> 600918.06 | Q42: =P42/$P$46 -> 0.61336055 | R42: =P42-G42 -> 4416.0595 | S42: =R42/$R$46 -> 0.30598597
A43: EMEA | B43: 147852 | C43: 173566 | D43: 103536 | E43: 129264 | F43: 150204 | G43: 176338 | I43: EMEA | J43: =F43-B43 -> 2352 | K43: =F43/B43-1 -> 0.0159078 | M43: =G43-C43 -> 2772 | N43: =G43/C43-1 -> 0.01597087 | P43: =C43/(1-K43) -> 176371.69 | Q43: =P43/$P$46 -> 0.1800236 | R43: =P43-G43 -> 33.685443 | S43: =R43/$R$46 -> 0.002334043
A44: APAC | B44: 95736 | C44: 107338 | D44: 69198 | E44: 80144 | F44: 99778 | G44: 109811 | I44: APAC | J44: =F44-B44 -> 4042 | K44: =F44/B44-1 -> 0.042220272 | M44: =G44-C44 -> 2473 | N44: =G44/C44-1 -> 0.023039371 | P44: =C44/(1-K44) -> 112069.61 | Q44: =P44/$P$46 -> 0.1143901 | R44: =P44-G44 -> 2258.6094 | S44: =R44/$R$46 -> 0.15649762
A45: LATAM | B45: 69053 | C45: 82618 | D45: 50574 | E45: 65121 | F45: 75265 | G45: 82631 | I45: LATAM | J45: =F45-B45 -> 6212 | K45: =F45/B45-1 -> 0.089959886 | M45: =G45-C45 -> 13 | N45: =G45/C45-1 -> 0.0001573507 | P45: =C45/(1-K45) -> 90785.009 | Q45: =P45/$P$46 -> 0.092664786 | R45: =P45-G45 -> 8154.0091 | S45: =R45/$R$46 -> 0.56498612 | T45: 2 customers left region in Q2, taking about 7k in volume away
A46: Grand Total | B46: 822060 | C46: 940140 | D46: 587002 | E46: 706563 | F46: 855266 | G46: 965282 | J46: =F46-B46 -> 33206 | K46: =F46/B46-1 -> 0.040393645 | M46: =G46-C46 -> 25142 | N46: =G46/C46-1 -> 0.026742826 | P46: =C46/(1-K46) -> 979714.23 | Q46: =P46/$P$46 -> 1 | R46: =P46-G46 -> 14432.229 | S46: =R46/$R$46 -> 1
T47: Q2 YoY growth slowed from Q1 growth of 4% down to 2.7% primarily driven by: .7% or 7k volume decline from loss of two customers in LATAM driving overall growth for region down from 9% in Q1 to flat in Q2 YoY
T48: Same store sales slower than expected in Q2 vs Q1 YoY, comprising majority of remaining variance
T49: - NAM client onboarding in Q2 2020 anniversaried in Q2 2021, slowing perceived growth
A51: Sum of Vol | C51: Years | D51: Quarters | E51: Date
C52: 2020 | D52: 2020 | E52: 2020 | F52: 2020 | G52: 2020 Total | H52: 2021 | I52: 2021 | J52: 2021 Total
C53: Qtr1 | D53: Qtr2 | E53: Qtr3 | F53: Qtr4 | H53: Qtr1 | I53: Qtr2
A54: Region Name | B54: CLID
A55: NAM | B55: CL69323 | C55: 95153 | D55: 101946 | E55: 67976 | F55: 74763 | G55: 339838 | H55: 98412 | I55: 105213 | J55: 203625 | L55: =I55/D55-1 -> 0.032046377
A56: NAM | B56: CL97995 | C56: 87224 | D56: 93457 | E56: 62305 | F56: 68540 | G56: 311526 | H56: 89246 | I56: 94887 | J56: 184133 | L56: =I56/D56-1 -> 0.015301155
A57: NAM | B57: CL38496 | C57: 68822 | D57: 79019 | E57: 48434 | F57: 58625 | G57: 254900 | H57: 69761 | I57: 81839 | J57: 151600 | L57: =I57/D57-1 -> 0.035687619
A58: NAM | B58: CL31601 | C58: 57353 | D58: 65847 | E58: 40364 | F58: 48865 | G58: 212429 | H58: 58740 | I58: 67226 | J58: 125966
A59: NAM | B59: CL33189 | C59: 51543 | D59: 63438 | E59: 35691 | F59: 47581 | G59: 198253 | H59: 52266 | I59: 65834 | J59: 118100
A60: NAM | B60: CL22140 | C60: 47869 | D60: 58910 | E60: 33137 | F60: 44184 | G60: 184100 | H60: 49385 | I60: 60071 | J60: 109456
A61: NAM | B61: CL37714 | C61: 38242 | D61: 43900 | E61: 26910 | F61: 32575 | G61: 141627 | H61: 39302 | I61: 44111 | J61: 83413
A62: NAM | B62: CL61534 | C62: 20189 | D62: 20896 | E62: 14525 | F62: 15234 | G62: 70844 | H62: 20317 | I62: 21097 | J62: 41414
A63: NAM | B63: CL46663 | C63: 8078 | D63: 8367 | E63: 5826 | F63: 6094 | G63: 28365 | H63: 8296 | I63: 8401 | J63: 16697
A64: NAM | B64: CL57593 | C64: 5024 | D64: 5769 | E64: 3536 | F64: 4278 | G64: 18607 | H64: 5035 | I64: 5895 | J64: 10930
A65: NAM | B65: CL96680 | C65: 4798 | D65: 5696 | E65: 3354 | F65: 4261 | G65: 18109 | H65: 4844 | I65: 5860 | J65: 10704
A66: NAM | B66: CL79204 | C66: 4934 | D66: 5281 | E66: 3520 | F66: 3875 | G66: 17610 | H66: 5039 | I66: 5432 | J66: 10471
A67: NAM | B67: CL83029 | C67: 4533 | D67: 5388 | E67: 3167 | F67: 4019 | G67: 17107 | H67: 4623 | I67: 5591 | J67: 10214
...

Sheet Summary
B1: Q2 2021 Widget Inc Overview
B2: All data as of 6/30/2021
B4: Q2 Volume | F4: Q2 Customers
B5: =Pivot!$G$46 -> 965282 | F5: =Pivot!$I$121 -> 50
B7: Prior Year | C7: % Change | F7: Prior Year | G7: % Change
B8: =Pivot!$C$46 -> 940140 | C8: =B5/B8-1 -> 0.026742826 | F8: =Pivot!$D$121 -> 50 | G8: =F5/F8-1 -> 0
B23: Volume | J23: Q2 YoY | M23: Q1 YoY
B24: Region | C24: Q1 2020 | D24: Q2 2020 | E24: Q3 2020 | F24: Q4 2020 | G24: Q1 2021 | H24: Q2 2021 | J24: # | K24: % | M24: # | N24: %
B25: NAM | C25: =SUMIFS(VolumebyClient[Vol],VolumebyClient[Region Name],Summary!$B25,VolumebyClient[Quarter],Summary!C$24) -> 509419 | D25: =SUMIFS(VolumebyClient[Vol],VolumebyClient[Region Name],Summary!$B25,VolumebyClient[Quarter],Summary!D$24) -> 576618 | E25: =SUMIFS(VolumebyClient[Vol],VolumebyClient[Region Name],Summary!$B25,VolumebyClient[Quarter],Summary!E$24) -> 363694 | F25: =SUMIFS(VolumebyClient[Vol],VolumebyClient[Region Name],Summary!$B25,VolumebyClient[Quarter],Summary!F$24) -> 432034 | G25: =SUMIFS(VolumebyClient[Vol],VolumebyClient[Region Name],Summary!$B25,VolumebyClient[Quarter],Summary!G$24) -> 530019 | H25: =SUMIFS(VolumebyClient[Vol],VolumebyClient[Region Name],Summary!$B25,VolumebyClient[Quarter],Summary!H$24) -> 596502 | J25: =H25-D25 -> 19884 | K25: =H25/D25-1 -> 0.034483835 | M25: =G25-C25 -> 20600 | N25: =G25/C25-1 -> 0.040438225
B26: EMEA | C26: =SUMIFS(VolumebyClient[Vol],VolumebyClient[Region Name],Summary!$B26,VolumebyClient[Quarter],Summary!C$24) -> 147852 | D26: =SUMIFS(VolumebyClient[Vol],VolumebyClient[Region Name],Summary!$B26,VolumebyClient[Quarter],Summary!D$24) -> 173566 | E26: =SUMIFS(VolumebyClient[Vol],VolumebyClient[Region Name],Summary!$B26,VolumebyClient[Quarter],Summary!E$24) -> 103536 | F26: =SUMIFS(VolumebyClient[Vol],VolumebyClient[Region Name],Summary!$B26,VolumebyClient[Quarter],Summary!F$24) -> 129264 | G26: =SUMIFS(VolumebyClient[Vol],VolumebyClient[Region Name],Summary!$B26,VolumebyClient[Quarter],Summary!G$24) -> 150204 | H26: =SUMIFS(VolumebyClient[Vol],VolumebyClient[Region Name],Summary!$B26,VolumebyClient[Quarter],Summary!H$24) -> 176338 | J26: =H26-D26 -> 2772 | K26: =H26/D26-1 -> 0.01597087 | M26: =G26-C26 -> 2352 | N26: =G26/C26-1 -> 0.0159078
B27: APAC | C27: =SUMIFS(VolumebyClient[Vol],VolumebyClient[Region Name],Summary!$B27,VolumebyClient[Quarter],Summary!C$24) -> 95736 | D27: =SUMIFS(VolumebyClient[Vol],VolumebyClient[Region Name],Summary!$B27,VolumebyClient[Quarter],Summary!D$24) -> 107338 | E27: =SUMIFS(VolumebyClient[Vol],VolumebyClient[Region Name],Summary!$B27,VolumebyClient[Quarter],Summary!E$24) -> 69198 | F27: =SUMIFS(VolumebyClient[Vol],VolumebyClient[Region Name],Summary!$B27,VolumebyClient[Quarter],Summary!F$24) -> 80144 | G27: =SUMIFS(VolumebyClient[Vol],VolumebyClient[Region Name],Summary!$B27,VolumebyClient[Quarter],Summary!G$24) -> 99778 | H27: =SUMIFS(VolumebyClient[Vol],VolumebyClient[Region Name],Summary!$B27,VolumebyClient[Quarter],Summary!H$24) -> 109811 | J27: =H27-D27 -> 2473 | K27: =H27/D27-1 -> 0.023039371 | M27: =G27-C27 -> 4042 | N27: =G27/C27-1 -> 0.042220272
B28: LATAM | C28: =SUMIFS(VolumebyClient[Vol],VolumebyClient[Region Name],Summary!$B28,VolumebyClient[Quarter],Summary!C$24) -> 69053 | D28: =SUMIFS(VolumebyClient[Vol],VolumebyClient[Region Name],Summary!$B28,VolumebyClient[Quarter],Summary!D$24) -> 82618 | E28: =SUMIFS(VolumebyClient[Vol],VolumebyClient[Region Name],Summary!$B28,VolumebyClient[Quarter],Summary!E$24) -> 50574 | F28: =SUMIFS(VolumebyClient[Vol],VolumebyClient[Region Name],Summary!$B28,VolumebyClient[Quarter],Summary!F$24) -> 65121 | G28: =SUMIFS(VolumebyClient[Vol],VolumebyClient[Region Name],Summary!$B28,VolumebyClient[Quarter],Summary!G$24) -> 75265 | H28: =SUMIFS(VolumebyClient[Vol],VolumebyClient[Region Name],Summary!$B28,VolumebyClient[Quarter],Summary!H$24) -> 82631 | J28: =H28-D28 -> 13 | K28: =H28/D28-1 -> 0.0001573507 | M28: =G28-C28 -> 6212 | N28: =G28/C28-1 -> 0.089959886
B29: Total | C29: =SUM(C25:C28) -> 822060 | D29: =SUM(D25:D28) -> 940140 | E29: =SUM(E25:E28) -> 587002 | F29: =SUM(F25:F28) -> 706563 | G29: =SUM(G25:G28) -> 855266 | H29: =SUM(H25:H28) -> 965282 | J29: =H29-D29 -> 25142 | K29: =H29/D29-1 -> 0.026742826 | M29: =G29-C29 -> 33206 | N29: =G29/C29-1 -> 0.040393645
B31: Customers | J31: Q2 YoY | M31: Q1 YoY
B32: Region | C32: Q1 2020 | D32: Q2 2020 | E32: Q3 2020 | F32: Q4 2020 | G32: Q1 2021 | H32: Q2 2021 | J32: # | K32: % | M32: # | N32: %
B33: NAM | C33: =ROUNDUP(COUNTIFS(VolumebyClient[Region Name],Summary!$B33,VolumebyClient[Quarter],Summary!C$32)/3,0) -> 18 | D33: =ROUNDUP(COUNTIFS(VolumebyClient[Region Name],Summary!$B33,VolumebyClient[Quarter],Summary!D$32)/3,0) -> 19 | E33: =ROUNDUP(COUNTIFS(VolumebyClient[Region Name],Summary!$B33,VolumebyClient[Quarter],Summary!E$32)/3,0) -> 19 | F33: =ROUNDUP(COUNTIFS(VolumebyClient[Region Name],Summary!$B33,VolumebyClient[Quarter],Summary!F$32)/3,0) -> 20 | G33: =ROUNDUP(COUNTIFS(VolumebyClient[Region Name],Summary!$B33,VolumebyClient[Quarter],Summary!G$32)/3,0) -> 20 | H33: =ROUNDUP(COUNTIFS(VolumebyClient[Region Name],Summary!$B33,VolumebyClient[Quarter],Summary!H$32)/3,0) -> 20 | J33: =H33-D33 -> 1 | K33: =H33/D33-1 -> 0.052631579 | M33: =G33-C33 -> 2 | N33: =G33/C33-1 -> 0.11111111
B34: EMEA | C34: =ROUNDUP(COUNTIFS(VolumebyClient[Region Name],Summary!$B34,VolumebyClient[Quarter],Summary!C$32)/3,0) -> 8 | D34: =ROUNDUP(COUNTIFS(VolumebyClient[Region Name],Summary!$B34,VolumebyClient[Quarter],Summary!D$32)/3,0) -> 8 | E34: =ROUNDUP(COUNTIFS(VolumebyClient[Region Name],Summary!$B34,VolumebyClient[Quarter],Summary!E$32)/3,0) -> 8 | F34: =ROUNDUP(COUNTIFS(VolumebyClient[Region Name],Summary!$B34,VolumebyClient[Quarter],Summary!F$32)/3,0) -> 8 | G34: =ROUNDUP(COUNTIFS(VolumebyClient[Region Name],Summary!$B34,VolumebyClient[Quarter],Summary!G$32)/3,0) -> 8 | H34: =ROUNDUP(COUNTIFS(VolumebyClient[Region Name],Summary!$B34,VolumebyClient[Quarter],Summary!H$32)/3,0) -> 8 | J34: =H34-D34 -> 0 | K34: =H34/D34-1 -> 0 | M34: =G34-C34 -> 0 | N34: =G34/C34-1 -> 0
B35: APAC | C35: =ROUNDUP(COUNTIFS(VolumebyClient[Region Name],Summary!$B35,VolumebyClient[Quarter],Summary!C$32)/3,0) -> 13 | D35: =ROUNDUP(COUNTIFS(VolumebyClient[Region Name],Summary!$B35,VolumebyClient[Quarter],Summary!D$32)/3,0) -> 13 | E35: =ROUNDUP(COUNTIFS(VolumebyClient[Region Name],Summary!$B35,VolumebyClient[Quarter],Summary!E$32)/3,0) -> 14 | F35: =ROUNDUP(COUNTIFS(VolumebyClient[Region Name],Summary!$B35,VolumebyClient[Quarter],Summary!F$32)/3,0) -> 14 | G35: =ROUNDUP(COUNTIFS(VolumebyClient[Region Name],Summary!$B35,VolumebyClient[Quarter],Summary!G$32)/3,0) -> 14 | H35: =ROUNDUP(COUNTIFS(VolumebyClient[Region Name],Summary!$B35,VolumebyClient[Quarter],Summary!H$32)/3,0) -> 13 | J35: =H35-D35 -> 0 | K35: =H35/D35-1 -> 0 | M35: =G35-C35 -> 1 | N35: =G35/C35-1 -> 0.076923077
B36: LATAM | C36: =ROUNDUP(COUNTIFS(VolumebyClient[Region Name],Summary!$B36,VolumebyClient[Quarter],Summary!C$32)/3,0) -> 10 | D36: =ROUNDUP(COUNTIFS(VolumebyClient[Region Name],Summary!$B36,VolumebyClient[Quarter],Summary!D$32)/3,0) -> 10 | E36: =ROUNDUP(COUNTIFS(VolumebyClient[Region Name],Summary!$B36,VolumebyClient[Quarter],Summary!E$32)/3,0) -> 11 | F36: =ROUNDUP(COUNTIFS(VolumebyClient[Region Name],Summary!$B36,VolumebyClient[Quarter],Summary!F$32)/3,0) -> 11 | G36: =ROUNDUP(COUNTIFS(VolumebyClient[Region Name],Summary!$B36,VolumebyClient[Quarter],Summary!G$32)/3,0) -> 11 | H36: =ROUNDUP(COUNTIFS(VolumebyClient[Region Name],Summary!$B36,VolumebyClient[Quarter],Summary!H$32)/3,0) -> 9 | J36: =H36-D36 -> -1 | K36: =H36/D36-1 -> -0.1 | M36: =G36-C36 -> 1 | N36: =G36/C36-1 -> 0.1
B37: Total | C37: =SUM(C33:C36) -> 49 | D37: =SUM(D33:D36) -> 50 | E37: =SUM(E33:E36) -> 52 | F37: =SUM(F33:F36) -> 53 | G37: =SUM(G33:G36) -> 53 | H37: =SUM(H33:H36) -> 50 | J37: =H37-D37 -> 0 | K37: =H37/D37-1 -> 0 | M37: =G37-C37 -> 4 | N37: =G37/C37-1 -> 0.081632653
B39: Average Volume / Customers | J39: Q2 YoY | M39: Q1 YoY
B40: Region | C40: Q1 2020 | D40: Q2 2020 | E40: Q3 2020 | F40: Q4 2020 | G40: Q1 2021 | H40: Q2 2021 | J40: # | K40: % | M40: # | N40: %
B41: NAM | C41: =C25/C33 -> 28301.056 | D41: =D25/D33 -> 30348.316 | E41: =E25/E33 -> 19141.789 | F41: =F25/F33 -> 21601.7 | G41: =G25/G33 -> 26500.95 | H41: =H25/H33 -> 29825.1 | J41: =H41-D41 -> -523.21579 | K41: =H41/D41-1 -> -0.017240357 | M41: =G41-C41 -> -1800.1056 | N41: =G41/C41-1 -> -0.063605598
B42: EMEA | C42: =C26/C34 -> 18481.5 | D42: =D26/D34 -> 21695.75 | E42: =E26/E34 -> 12942 | F42: =F26/F34 -> 16158 | G42: =G26/G34 -> 18775.5 | H42: =H26/H34 -> 22042.25 | J42: =H42-D42 -> 346.5 | K42: =H42/D42-1 -> 0.01597087 | M42: =G42-C42 -> 294 | N42: =G42/C42-1 -> 0.0159078
B43: APAC | C43: =C27/C35 -> 7364.3077 | D43: =D27/D35 -> 8256.7692 | E43: =E27/E35 -> 4942.7143 | F43: =F27/F35 -> 5724.5714 | G43: =G27/G35 -> 7127 | H43: =H27/H35 -> 8447 | J43: =H43-D43 -> 190.23077 | K43: =H43/D43-1 -> 0.023039371 | M43: =G43-C43 -> -237.30769 | N43: =G43/C43-1 -> -0.032224033
B44: LATAM | C44: =C28/C36 -> 6905.3 | D44: =D28/D36 -> 8261.8 | E44: =E28/E36 -> 4597.6364 | F44: =F28/F36 -> 5920.0909 | G44: =G28/G36 -> 6842.2727 | H44: =H28/H36 -> 9181.2222 | J44: =H44-D44 -> 919.42222 | K44: =H44/D44-1 -> 0.11128595 | M44: =G44-C44 -> -63.027273 | N44: =G44/C44-1 -> -0.0091273765
B45: Total | C45: =C29/C37 -> 16776.735 | D45: =D29/D37 -> 18802.8 | E45: =E29/E37 -> 11288.5 | F45: =F29/F37 -> 13331.377 | G45: =G29/G37 -> 16137.094 | H45: =H29/H37 -> 19305.64 | J45: =H45-D45 -> 502.84 | K45: =H45/D45-1 -> 0.026742826 | M45: =G45-C45 -> -639.64035 | N45: =G45/C45-1 -> -0.03812663
B47: Key Notes | J47: =D29*(1+N29) -> 978115.68
J48: =J47-H29 -> 12833.682 | K48: =7000/J48 -> 0.54543974
B49: Q2 YoY growth slowed from Q1 growth of 4% down to 2.7% or (~13k)primarily driven by:
B50: .7% or 7k volume or 55% of decline from loss of two customers in LATAM driving overall growth for region down from 9% in Q1 to flat in Q2 YoY
B51: -NAM client onboarding in Q2 2020 anniversaried in Q2 2021, slowing perceived growth and amplifying Q1 growth by ~5k units, or 1%

Sheet Volume Data
A1: CLID | B1: Date | C1: Vol | D1: LEN | E1: Xlookup Region ID | F1: Index Match Region ID | G1: Region Name | H1: Quarter | I1: Quarter by Vlookup | L1: Date Start | M1: Date End | N1: Name
A2: CL11420 | B2: 43921 | C2: 884 | D2: =LEN(VolumebyClient[[#This Row],[CLID]]) -> 7 | F2: =INDEX(GeobyClient[GEOID],MATCH(VolumebyClient[[#This Row],[CLID]],GeobyClient[Right],0)) -> GEO1004 | G2: =VLOOKUP(VolumebyClient[[#This Row],[Index Match Region ID]],GEONames[[GEOID]:[GEO NAME]],2,FALSE) -> LATAM | H2: ="Q"&ROUNDUP(MONTH(VolumebyClient[[#This Row],[Date]])/3,0)&" "&YEAR(VolumebyClient[[#This Row],[Date]]) -> Q1 2020 | I2: =VLOOKUP(VolumebyClient[[#This Row],[Date]],Quarters[],3,TRUE) -> Q1 2020 | L2: 43831 | M2: 43921 | N2: Q1 2020
A3: CL11420 | B3: 43951 | C3: 886 | D3: =LEN(VolumebyClient[[#This Row],[CLID]]) -> 7 | F3: =INDEX(GeobyClient[GEOID],MATCH(VolumebyClient[[#This Row],[CLID]],GeobyClient[Right],0)) -> GEO1004 | G3: =VLOOKUP(VolumebyClient[[#This Row],[Index Match Region ID]],GEONames[[GEOID]:[GEO NAME]],2,FALSE) -> LATAM | H3: ="Q"&ROUNDUP(MONTH(VolumebyClient[[#This Row],[Date]])/3,0)&" "&YEAR(VolumebyClient[[#This Row],[Date]]) -> Q2 2020 | I3: =VLOOKUP(VolumebyClient[[#This Row],[Date]],Quarters[],3,TRUE) -> Q2 2020 | L3: 43922 | M3: 44012 | N3: Q2 2020
A4: CL11420 | B4: 43982 | C4: 968 | D4: =LEN(VolumebyClient[[#This Row],[CLID]]) -> 7 | F4: =INDEX(GeobyClient[GEOID],MATCH(VolumebyClient[[#This Row],[CLID]],GeobyClient[Right],0)) -> GEO1004 | G4: =VLOOKUP(VolumebyClient[[#This Row],[Index Match Region ID]],GEONames[[GEOID]:[GEO NAME]],2,FALSE) -> LATAM | H4: ="Q"&ROUNDUP(MONTH(VolumebyClient[[#This Row],[Date]])/3,0)&" "&YEAR(VolumebyClient[[#This Row],[Date]]) -> Q2 2020 | I4: =VLOOKUP(VolumebyClient[[#This Row],[Date]],Quarters[],3,TRUE) -> Q2 2020 | L4: 44013 | M4: 44104 | N4: Q3 2020
A5: CL11420 | B5: 44012 | C5: 564 | D5: =LEN(VolumebyClient[[#This Row],[CLID]]) -> 7 | F5: =INDEX(GeobyClient[GEOID],MATCH(VolumebyClient[[#This Row],[CLID]],GeobyClient[Right],0)) -> GEO1004 | G5: =VLOOKUP(VolumebyClient[[#This Row],[Index Match Region ID]],GEONames[[GEOID]:[GEO NAME]],2,FALSE) -> LATAM | H5: ="Q"&ROUNDUP(MONTH(VolumebyClient[[#This Row],[Date]])/3,0)&" "&YEAR(VolumebyClient[[#This Row],[Date]]) -> Q2 2020 | I5: =VLOOKUP(VolumebyClient[[#This Row],[Date]],Quarters[],3,TRUE) -> Q2 2020 | L5: 44105 | M5: 44196 | N5: Q4 2020
A6: CL11420 | B6: 44043 | C6: 648 | D6: =LEN(VolumebyClient[[#This Row],[CLID]]) -> 7 | F6: =INDEX(GeobyClient[GEOID],MATCH(VolumebyClient[[#This Row],[CLID]],GeobyClient[Right],0)) -> GEO1004 | G6: =VLOOKUP(VolumebyClient[[#This Row],[Index Match Region ID]],GEONames[[GEOID]:[GEO NAME]],2,FALSE) -> LATAM | H6: ="Q"&ROUNDUP(MONTH(VolumebyClient[[#This Row],[Date]])/3,0)&" "&YEAR(VolumebyClient[[#This Row],[Date]]) -> Q3 2020 | I6: =VLOOKUP(VolumebyClient[[#This Row],[Date]],Quarters[],3,TRUE) -> Q3 2020 | L6: 44197 | M6: 44286 | N6: Q1 2021
A7: CL11420 | B7: 44074 | C7: 406 | D7: =LEN(VolumebyClient[[#This Row],[CLID]]) -> 7 | F7: =INDEX(GeobyClient[GEOID],MATCH(VolumebyClient[[#This Row],[CLID]],GeobyClient[Right],0)) -> GEO1004 | G7: =VLOOKUP(VolumebyClient[[#This Row],[Index Match Region ID]],GEONames[[GEOID]:[GEO NAME]],2,FALSE) -> LATAM | H7: ="Q"&ROUNDUP(MONTH(VolumebyClient[[#This Row],[Date]])/3,0)&" "&YEAR(VolumebyClient[[#This Row],[Date]]) -> Q3 2020 | I7: =VLOOKUP(VolumebyClient[[#This Row],[Date]],Quarters[],3,TRUE) -> Q3 2020 | L7: 44287 | M7: 44377 | N7: Q2 2021
A8: CL11420 | B8: 44104 | C8: 569 | D8: =LEN(VolumebyClient[[#This Row],[CLID]]) -> 7 | F8: =INDEX(GeobyClient[GEOID],MATCH(VolumebyClient[[#This Row],[CLID]],GeobyClient[Right],0)) -> GEO1004 | G8: =VLOOKUP(VolumebyClient[[#This Row],[Index Match Region ID]],GEONames[[GEOID]:[GEO NAME]],2,FALSE) -> LATAM | H8: ="Q"&ROUNDUP(MONTH(VolumebyClient[[#This Row],[Date]])/3,0)&" "&YEAR(VolumebyClient[[#This Row],[Date]]) -> Q3 2020 | I8: =VLOOKUP(VolumebyClient[[#This Row],[Date]],Quarters[],3,TRUE) -> Q3 2020
A9: CL11420 | B9: 44135 | C9: 487 | D9: =LEN(VolumebyClient[[#This Row],[CLID]]) -> 7 | F9: =INDEX(GeobyClient[GEOID],MATCH(VolumebyClient[[#This Row],[CLID]],GeobyClient[Right],0)) -> GEO1004 | G9: =VLOOKUP(VolumebyClient[[#This Row],[Index Match Region ID]],GEONames[[GEOID]:[GEO NAME]],2,FALSE) -> LATAM | H9: ="Q"&ROUNDUP(MONTH(VolumebyClient[[#This Row],[Date]])/3,0)&" "&YEAR(VolumebyClient[[#This Row],[Date]]) -> Q4 2020 | I9: =VLOOKUP(VolumebyClient[[#This Row],[Date]],Quarters[],3,TRUE) -> Q4 2020
A10: CL11420 | B10: 44165 | C10: 729 | D10: =LEN(VolumebyClient[[#This Row],[CLID]]) -> 7 | F10: =INDEX(GeobyClient[GEOID],MATCH(VolumebyClient[[#This Row],[CLID]],GeobyClient[Right],0)) -> GEO1004 | G10: =VLOOKUP(VolumebyClient[[#This Row],[Index Match Region ID]],GEONames[[GEOID]:[GEO NAME]],2,FALSE) -> LATAM | H10: ="Q"&ROUNDUP(MONTH(VolumebyClient[[#This Row],[Date]])/3,0)&" "&YEAR(VolumebyClient[[#This Row],[Date]]) -> Q4 2020 | I10: =VLOOKUP(VolumebyClient[[#This Row],[Date]],Quarters[],3,TRUE) -> Q4 2020
A11: CL11420 | B11: 44196 | C11: 565 | D11: =LEN(VolumebyClient[[#This Row],[CLID]]) -> 7 | F11: =INDEX(GeobyClient[GEOID],MATCH(VolumebyClient[[#This Row],[CLID]],GeobyClient[Right],0)) -> GEO1004 | G11: =VLOOKUP(VolumebyClient[[#This Row],[Index Match Region ID]],GEONames[[GEOID]:[GEO NAME]],2,FALSE) -> LATAM | H11: ="Q"&ROUNDUP(MONTH(VolumebyClient[[#This Row],[Date]])/3,0)&" "&YEAR(VolumebyClient[[#This Row],[Date]]) -> Q4 2020 | I11: =VLOOKUP(VolumebyClient[[#This Row],[Date]],Quarters[],3,TRUE) -> Q4 2020
A12: CL11420 | B12: 44377 | C12: 561 | D12: =LEN(VolumebyClient[[#This Row],[CLID]]) -> 7 | F12: =INDEX(GeobyClient[GEOID],MATCH(VolumebyClient[[#This Row],[CLID]],GeobyClient[Right],0)) -> GEO1004 | G12: =VLOOKUP(VolumebyClient[[#This Row],[Index Match Region ID]],GEONames[[GEOID]:[GEO NAME]],2,FALSE) -> LATAM | H12: ="Q"&ROUNDUP(MONTH(VolumebyClient[[#This Row],[Date]])/3,0)&" "&YEAR(VolumebyClient[[#This Row],[Date]]) -> Q2 2021 | I12: =VLOOKUP(VolumebyClient[[#This Row],[Date]],Quarters[],3,TRUE) -> Q2 2021
A13: CL11420 | B13: 44347 | C13: 1014 | D13: =LEN(VolumebyClient[[#This Row],[CLID]]) -> 7 | F13: =INDEX(GeobyClient[GEOID],MATCH(VolumebyClient[[#This Row],[CLID]],GeobyClient[Right],0)) -> GEO1004 | G13: =VLOOKUP(VolumebyClient[[#This Row],[Index Match Region ID]],GEONames[[GEOID]:[GEO NAME]],2,FALSE) -> LATAM | H13: ="Q"&ROUNDUP(MONTH(VolumebyClient[[#This Row],[Date]])/3,0)&" "&YEAR(VolumebyClient[[#This Row],[Date]]) -> Q2 2021 | I13: =VLOOKUP(VolumebyClient[[#This Row],[Date]],Quarters[],3,TRUE) -> Q2 2021
A14: CL11420 | B14: 44316 | C14: 878 | D14: =LEN(VolumebyClient[[#This Row],[CLID]]) -> 7 | F14: =INDEX(GeobyClient[GEOID],MATCH(VolumebyClient[[#This Row],[CLID]],GeobyClient[Right],0)) -> GEO1004 | G14: =VLOOKUP(VolumebyClient[[#This Row],[Index Match Region ID]],GEONames[[GEOID]:[GEO NAME]],2,FALSE) -> LATAM | H14: ="Q"&ROUNDUP(MONTH(VolumebyClient[[#This Row],[Date]])/3,0)&" "&YEAR(VolumebyClient[[#This Row],[Date]]) -> Q2 2021 | I14: =VLOOKUP(VolumebyClient[[#This Row],[Date]],Quarters[],3,TRUE) -> Q2 2021
A15: CL11420 | B15: 44286 | C15: 922 | D15: =LEN(VolumebyClient[[#This Row],[CLID]]) -> 7 | F15: =INDEX(GeobyClient[GEOID],MATCH(VolumebyClient[[#This Row],[CLID]],GeobyClient[Right],0)) -> GEO1004 | G15: =VLOOKUP(VolumebyClient[[#This Row],[Index Match Region ID]],GEONames[[GEOID]:[GEO NAME]],2,FALSE) -> LATAM | H15: ="Q"&ROUNDUP(MONTH(VolumebyClient[[#This Row],[Date]])/3,0)&" "&YEAR(VolumebyClient[[#This Row],[Date]]) -> Q1 2021 | I15: =VLOOKUP(VolumebyClient[[#This Row],[Date]],Quarters[],3,TRUE) -> Q1 2021
A16: CL11420 | B16: 44255 | C16: 668 | D16: =LEN(VolumebyClient[[#This Row],[CLID]]) -> 7 | F16: =INDEX(GeobyClient[GEOID],MATCH(VolumebyClient[[#This Row],[CLID]],GeobyClient[Right],0)) -> GEO1004 | G16: =VLOOKUP(VolumebyClient[[#This Row],[Index Match Region ID]],GEONames[[GEOID]:[GEO NAME]],2,FALSE) -> LATAM | H16: ="Q"&ROUNDUP(MONTH(VolumebyClient[[#This Row],[Date]])/3,0)&" "&YEAR(VolumebyClient[[#This Row],[Date]]) -> Q1 2021 | I16: =VLOOKUP(VolumebyClient[[#This Row],[Date]],Quarters[],3,TRUE) -> Q1 2021
A17: CL11420 | B17: 44227 | C17: 725 | D17: =LEN(VolumebyClient[[#This Row],[CLID]]) -> 7 | F17: =INDEX(GeobyClient[GEOID],MATCH(VolumebyClient[[#This Row],[CLID]],GeobyClient[Right],0)) -> GEO1004 | G17: =VLOOKUP(VolumebyClient[[#This Row],[Index Match Region ID]],GEONames[[GEOID]:[GEO NAME]],2,FALSE) -> LATAM | H17: ="Q"&ROUNDUP(MONTH(VolumebyClient[[#This Row],[Date]])/3,0)&" "&YEAR(VolumebyClient[[#This Row],[Date]]) -> Q1 2021 | I17: =VLOOKUP(VolumebyClient[[#This Row],[Date]],Quarters[],3,TRUE) -> Q1 2021
A18: CL13213 | B18: 43861 | C18: 1194 | D18: =LEN(VolumebyClient[[#This Row],[CLID]]) -> 7 | F18: =INDEX(GeobyClient[GEOID],MATCH(VolumebyClient[[#This Row],[CLID]],GeobyClient[Right],0)) -> GEO1001 | G18: =VLOOKUP(VolumebyClient[[#This Row],[Index Match Region ID]],GEONames[[GEOID]:[GEO NAME]],2,FALSE) -> NAM | H18: ="Q"&ROUNDUP(MONTH(VolumebyClient[[#This Row],[Date]])/3,0)&" "&YEAR(VolumebyClient[[#This Row],[Date]]) -> Q1 2020 | I18: =VLOOKUP(VolumebyClient[[#This Row],[Date]],Quarters[],3,TRUE) -> Q1 2020
A19: CL13213 | B19: 43890 | C19: 942 | D19: =LEN(VolumebyClient[[#This Row],[CLID]]) -> 7 | F19: =INDEX(GeobyClient[GEOID],MATCH(VolumebyClient[[#This Row],[CLID]],GeobyClient[Right],0)) -> GEO1001 | G19: =VLOOKUP(VolumebyClient[[#This Row],[Index Match Region ID]],GEONames[[GEOID]:[GEO NAME]],2,FALSE) -> NAM | H19: ="Q"&ROUNDUP(MONTH(VolumebyClient[[#This Row],[Date]])/3,0)&" "&YEAR(VolumebyClient[[#This Row],[Date]]) -> Q1 2020 | I19: =VLOOKUP(VolumebyClient[[#This Row],[Date]],Quarters[],3,TRUE) -> Q1 2020
... A908: CL99768 | B908: 44227 | C908: 222 | D908: =LEN(VolumebyClient[[#This Row],[CLID]]) -> 7 | F908: =INDEX(GeobyClient[GEOID],MATCH(VolumebyClient[[#This Row],[CLID]],GeobyClient[Right],0)) -> GEO1002 | G908: =VLOOKUP(VolumebyClient[[#This Row],[Index Match Region ID]],GEONames[[GEOID]:[GEO NAME]],2,FALSE) -> APAC | H908: ="Q"&ROUNDUP(MONTH(VolumebyClient[[#This Row],[Date]])/3,0)&" "&YEAR(VolumebyClient[[#This Row],[Date]]) -> Q1 2021 | I908: =VLOOKUP(VolumebyClient[[#This Row],[Date]],Quarters[],3,TRUE) -> Q1 2021

Sheet Geo Data
A1: CLID | B1: GEOID | C1: LEN | D1: Mid | E1: Right | F1: Test | G1: Region | K1: GEOID | L1: GEO NAME | M1: Volume
A2: C-CL69323 | B2: GEO1001 | C2: =LEN(GeobyClient[[#This Row],[CLID]]) -> 9 | D2: =MID(GeobyClient[[#This Row],[CLID]],3,7) -> CL69323 | E2: =RIGHT(GeobyClient[[#This Row],[CLID]],7) -> CL69323 | F2: =GeobyClient[[#This Row],[Right]]=GeobyClient[[#This Row],[Mid]] -> TRUE | G2: =VLOOKUP(GeobyClient[[#This Row],[GEOID]],GEONames[[GEOID]:[GEO NAME]],2,FALSE) -> NAM | K2: GEO1001 | L2: NAM | M2: =SUMIFS(VolumebyClient[Vol],VolumebyClient[Index Match Region ID],GEONames[[#This Row],[GEOID]]) -> 3008286
A3: C-CL97995 | B3: GEO1001 | C3: =LEN(GeobyClient[[#This Row],[CLID]]) -> 9 | D3: =MID(GeobyClient[[#This Row],[CLID]],3,7) -> CL97995 | E3: =RIGHT(GeobyClient[[#This Row],[CLID]],7) -> CL97995 | F3: =GeobyClient[[#This Row],[Right]]=GeobyClient[[#This Row],[Mid]] -> TRUE | G3: =VLOOKUP(GeobyClient[[#This Row],[GEOID]],GEONames[[GEOID]:[GEO NAME]],2,FALSE) -> NAM | K3: GEO1003 | L3: EMEA | M3: =SUMIFS(VolumebyClient[Vol],VolumebyClient[Index Match Region ID],GEONames[[#This Row],[GEOID]]) -> 880760
A4: C-CL87299 | B4: GEO1003 | C4: =LEN(GeobyClient[[#This Row],[CLID]]) -> 9 | D4: =MID(GeobyClient[[#This Row],[CLID]],3,7) -> CL87299 | E4: =RIGHT(GeobyClient[[#This Row],[CLID]],7) -> CL87299 | F4: =GeobyClient[[#This Row],[Right]]=GeobyClient[[#This Row],[Mid]] -> TRUE | G4: =VLOOKUP(GeobyClient[[#This Row],[GEOID]],GEONames[[GEOID]:[GEO NAME]],2,FALSE) -> EMEA | K4: GEO1002 | L4: APAC | M4: =SUMIFS(VolumebyClient[Vol],VolumebyClient[Index Match Region ID],GEONames[[#This Row],[GEOID]]) -> 562005
A5: C-CL38496 | B5: GEO1001 | C5: =LEN(GeobyClient[[#This Row],[CLID]]) -> 9 | D5: =MID(GeobyClient[[#This Row],[CLID]],3,7) -> CL38496 | E5: =RIGHT(GeobyClient[[#This Row],[CLID]],7) -> CL38496 | F5: =GeobyClient[[#This Row],[Right]]=GeobyClient[[#This Row],[Mid]] -> TRUE | G5: =VLOOKUP(GeobyClient[[#This Row],[GEOID]],GEONames[[GEOID]:[GEO NAME]],2,FALSE) -> NAM | K5: GEO1004 | L5: LATAM | M5: =SUMIFS(VolumebyClient[Vol],VolumebyClient[Index Match Region ID],GEONames[[#This Row],[GEOID]]) -> 425262
A6: C-CL75562 | B6: GEO1003 | C6: =LEN(GeobyClient[[#This Row],[CLID]]) -> 9 | D6: =MID(GeobyClient[[#This Row],[CLID]],3,7) -> CL75562 | E6: =RIGHT(GeobyClient[[#This Row],[CLID]],7) -> CL75562 | F6: =GeobyClient[[#This Row],[Right]]=GeobyClient[[#This Row],[Mid]] -> TRUE | G6: =VLOOKUP(GeobyClient[[#This Row],[GEOID]],GEONames[[GEOID]:[GEO NAME]],2,FALSE) -> EMEA | M6: =SUBTOTAL(109,GEONames[Volume]) -> 4876313
A7: C-CL31601 | B7: GEO1001 | C7: =LEN(GeobyClient[[#This Row],[CLID]]) -> 9 | D7: =MID(GeobyClient[[#This Row],[CLID]],3,7) -> CL31601 | E7: =RIGHT(GeobyClient[[#This Row],[CLID]],7) -> CL31601 | F7: =GeobyClient[[#This Row],[Right]]=GeobyClient[[#This Row],[Mid]] -> TRUE | G7: =VLOOKUP(GeobyClient[[#This Row],[GEOID]],GEONames[[GEOID]:[GEO NAME]],2,FALSE) -> NAM | M7: =GEONames[[#Totals],[Volume]]-SUM(VolumebyClient[Vol]) -> 0
A8: C-CL33189 | B8: GEO1001 | C8: =LEN(GeobyClient[[#This Row],[CLID]]) -> 9 | D8: =MID(GeobyClient[[#This Row],[CLID]],3,7) -> CL33189 | E8: =RIGHT(GeobyClient[[#This Row],[CLID]],7) -> CL33189 | F8: =GeobyClient[[#This Row],[Right]]=GeobyClient[[#This Row],[Mid]] -> TRUE | G8: =VLOOKUP(GeobyClient[[#This Row],[GEOID]],GEONames[[GEOID]:[GEO NAME]],2,FALSE) -> NAM
A9: C-CL22140 | B9: GEO1001 | C9: =LEN(GeobyClient[[#This Row],[CLID]]) -> 9 | D9: =MID(GeobyClient[[#This Row],[CLID]],3,7) -> CL22140 | E9: =RIGHT(GeobyClient[[#This Row],[CLID]],7) -> CL22140 | F9: =GeobyClient[[#This Row],[Right]]=GeobyClient[[#This Row],[Mid]] -> TRUE | G9: =VLOOKUP(GeobyClient[[#This Row],[GEOID]],GEONames[[GEOID]:[GEO NAME]],2,FALSE) -> NAM
A10: C-CL49960 | B10: GEO1002 | C10: =LEN(GeobyClient[[#This Row],[CLID]]) -> 9 | D10: =MID(GeobyClient[[#This Row],[CLID]],3,7) -> CL49960 | E10: =RIGHT(GeobyClient[[#This Row],[CLID]],7) -> CL49960 | F10: =GeobyClient[[#This Row],[Right]]=GeobyClient[[#This Row],[Mid]] -> TRUE | G10: =VLOOKUP(GeobyClient[[#This Row],[GEOID]],GEONames[[GEOID]:[GEO NAME]],2,FALSE) -> APAC
A11: C-CL43946 | B11: GEO1004 | C11: =LEN(GeobyClient[[#This Row],[CLID]]) -> 9 | D11: =MID(GeobyClient[[#This Row],[CLID]],3,7) -> CL43946 | E11: =RIGHT(GeobyClient[[#This Row],[CLID]],7) -> CL43946 | F11: =GeobyClient[[#This Row],[Right]]=GeobyClient[[#This Row],[Mid]] -> TRUE | G11: =VLOOKUP(GeobyClient[[#This Row],[GEOID]],GEONames[[GEOID]:[GEO NAME]],2,FALSE) -> LATAM
A12: C-CL37714 | B12: GEO1001 | C12: =LEN(GeobyClient[[#This Row],[CLID]]) -> 9 | D12: =MID(GeobyClient[[#This Row],[CLID]],3,7) -> CL37714 | E12: =RIGHT(GeobyClient[[#This Row],[CLID]],7) -> CL37714 | F12: =GeobyClient[[#This Row],[Right]]=GeobyClient[[#This Row],[Mid]] -> TRUE | G12: =VLOOKUP(GeobyClient[[#This Row],[GEOID]],GEONames[[GEOID]:[GEO NAME]],2,FALSE) -> NAM
A13: C-CL75274 | B13: GEO1002 | C13: =LEN(GeobyClient[[#This Row],[CLID]]) -> 9 | D13: =MID(GeobyClient[[#This Row],[CLID]],3,7) -> CL75274 | E13: =RIGHT(GeobyClient[[#This Row],[CLID]],7) -> CL75274 | F13: =GeobyClient[[#This Row],[Right]]=GeobyClient[[#This Row],[Mid]] -> TRUE | G13: =VLOOKUP(GeobyClient[[#This Row],[GEOID]],GEONames[[GEOID]:[GEO NAME]],2,FALSE) -> APAC
A14: C-CL61534 | B14: GEO1001 | C14: =LEN(GeobyClient[[#This Row],[CLID]]) -> 9 | D14: =MID(GeobyClient[[#This Row],[CLID]],3,7) -> CL61534 | E14: =RIGHT(GeobyClient[[#This Row],[CLID]],7) -> CL61534 | F14: =GeobyClient[[#This Row],[Right]]=GeobyClient[[#This Row],[Mid]] -> TRUE | G14: =VLOOKUP(GeobyClient[[#This Row],[GEOID]],GEONames[[GEOID]:[GEO NAME]],2,FALSE) -> NAM
A15: C-CL85641 | B15: GEO1004 | C15: =LEN(GeobyClient[[#This Row],[CLID]]) -> 9 | D15: =MID(GeobyClient[[#This Row],[CLID]],3,7) -> CL85641 | E15: =RIGHT(GeobyClient[[#This Row],[CLID]],7) -> CL85641 | F15: =GeobyClient[[#This Row],[Right]]=GeobyClient[[#This Row],[Mid]] -> TRUE | G15: =VLOOKUP(GeobyClient[[#This Row],[GEOID]],GEONames[[GEOID]:[GEO NAME]],2,FALSE) -> LATAM
A16: C-CL46663 | B16: GEO1001 | C16: =LEN(GeobyClient[[#This Row],[CLID]]) -> 9 | D16: =MID(GeobyClient[[#This Row],[CLID]],3,7) -> CL46663 | E16: =RIGHT(GeobyClient[[#This Row],[CLID]],7) -> CL46663 | F16: =GeobyClient[[#This Row],[Right]]=GeobyClient[[#This Row],[Mid]] -> TRUE | G16: =VLOOKUP(GeobyClient[[#This Row],[GEOID]],GEONames[[GEOID]:[GEO NAME]],2,FALSE) -> NAM
A17: C-CL17270 | B17: GEO1001 | C17: =LEN(GeobyClient[[#This Row],[CLID]]) -> 9 | D17: =MID(GeobyClient[[#This Row],[CLID]],3,7) -> CL17270 | E17: =RIGHT(GeobyClient[[#This Row],[CLID]],7) -> CL17270 | F17: =GeobyClient[[#This Row],[Right]]=GeobyClient[[#This Row],[Mid]] -> TRUE | G17: =VLOOKUP(GeobyClient[[#This Row],[GEOID]],GEONames[[GEOID]:[GEO NAME]],2,FALSE) -> NAM
A18: C-CL57593 | B18: GEO1001 | C18: =LEN(GeobyClient[[#This Row],[CLID]]) -> 9 | D18: =MID(GeobyClient[[#This Row],[CLID]],3,7) -> CL57593 | E18: =RIGHT(GeobyClient[[#This Row],[CLID]],7) -> CL57593 | F18: =GeobyClient[[#This Row],[Right]]=GeobyClient[[#This Row],[Mid]] -> TRUE | G18: =VLOOKUP(GeobyClient[[#This Row],[GEOID]],GEONames[[GEOID]:[GEO NAME]],2,FALSE) -> NAM
A19: C-CL96680 | B19: GEO1001 | C19: =LEN(GeobyClient[[#This Row],[CLID]]) -> 9 | D19: =MID(GeobyClient[[#This Row],[CLID]],3,7) -> CL96680 | E19: =RIGHT(GeobyClient[[#This Row],[CLID]],7) -> CL96680 | F19: =GeobyClient[[#This Row],[Right]]=GeobyClient[[#This Row],[Mid]] -> TRUE | G19: =VLOOKUP(GeobyClient[[#This Row],[GEOID]],GEONames[[GEOID]:[GEO NAME]],2,FALSE) -> NAM
... A54: C-CL82440 | B54: GEO1002 | C54: =LEN(GeobyClient[[#This Row],[CLID]]) -> 9 | D54: =MID(GeobyClient[[#This Row],[CLID]],3,7) -> CL82440 | E54: =RIGHT(GeobyClient[[#This Row],[CLID]],7) -> CL82440 | F54: =GeobyClient[[#This Row],[Right]]=GeobyClient[[#This Row],[Mid]] -> TRUE | G54: =VLOOKUP(GeobyClient[[#This Row],[GEOID]],GEONames[[GEOID]:[GEO NAME]],2,FALSE) -> APAC
